[2023-03-07T07:49:34.362+0000] {taskinstance.py:1083} INFO - Dependencies all met for <TaskInstance: hook_dag.hook_task manual__2023-03-07T07:49:32.464872+00:00 [queued]>
[2023-03-07T07:49:34.378+0000] {taskinstance.py:1083} INFO - Dependencies all met for <TaskInstance: hook_dag.hook_task manual__2023-03-07T07:49:32.464872+00:00 [queued]>
[2023-03-07T07:49:34.379+0000] {taskinstance.py:1279} INFO - 
--------------------------------------------------------------------------------
[2023-03-07T07:49:34.379+0000] {taskinstance.py:1280} INFO - Starting attempt 1 of 2
[2023-03-07T07:49:34.379+0000] {taskinstance.py:1281} INFO - 
--------------------------------------------------------------------------------
[2023-03-07T07:49:34.401+0000] {taskinstance.py:1300} INFO - Executing <Task(PythonOperator): hook_task> on 2023-03-07 07:49:32.464872+00:00
[2023-03-07T07:49:34.408+0000] {standard_task_runner.py:55} INFO - Started process 7630 to run task
[2023-03-07T07:49:34.413+0000] {standard_task_runner.py:82} INFO - Running: ['***', 'tasks', 'run', 'hook_dag', 'hook_task', 'manual__2023-03-07T07:49:32.464872+00:00', '--job-id', '39', '--raw', '--subdir', 'DAGS_FOLDER/pg-hook.py', '--cfg-path', '/tmp/tmptnaj6mg2']
[2023-03-07T07:49:34.414+0000] {standard_task_runner.py:83} INFO - Job 39: Subtask hook_task
[2023-03-07T07:49:34.511+0000] {task_command.py:388} INFO - Running <TaskInstance: hook_dag.hook_task manual__2023-03-07T07:49:32.464872+00:00 [running]> on host 4d3923509bb6
[2023-03-07T07:49:34.600+0000] {taskinstance.py:1509} INFO - Exporting the following env vars:
AIRFLOW_CTX_DAG_OWNER=***
AIRFLOW_CTX_DAG_ID=hook_dag
AIRFLOW_CTX_TASK_ID=hook_task
AIRFLOW_CTX_EXECUTION_DATE=2023-03-07T07:49:32.464872+00:00
AIRFLOW_CTX_TRY_NUMBER=1
AIRFLOW_CTX_DAG_RUN_ID=manual__2023-03-07T07:49:32.464872+00:00
[2023-03-07T07:49:34.614+0000] {base.py:73} INFO - Using connection ID 'postgre_sql' for task execution.
[2023-03-07T07:49:34.620+0000] {taskinstance.py:1768} ERROR - Task failed with exception
Traceback (most recent call last):
  File "/home/airflow/.local/lib/python3.7/site-packages/airflow/operators/python.py", line 175, in execute
    return_value = self.execute_callable()
  File "/home/airflow/.local/lib/python3.7/site-packages/airflow/operators/python.py", line 192, in execute_callable
    return self.python_callable(*self.op_args, **self.op_kwargs)
  File "/opt/airflow/dags/pg-hook.py", line 21, in get_activated_sources
    cursor.execute(request)
psycopg2.errors.UndefinedTable: relation "course.source" does not exist
LINE 1: SELECT * FROM course.source
                      ^

[2023-03-07T07:49:34.633+0000] {taskinstance.py:1323} INFO - Marking task as UP_FOR_RETRY. dag_id=hook_dag, task_id=hook_task, execution_date=20230307T074932, start_date=20230307T074934, end_date=20230307T074934
[2023-03-07T07:49:34.648+0000] {standard_task_runner.py:105} ERROR - Failed to execute job 39 for task hook_task (relation "course.source" does not exist
LINE 1: SELECT * FROM course.source
                      ^
; 7630)
[2023-03-07T07:49:34.664+0000] {local_task_job.py:208} INFO - Task exited with return code 1
[2023-03-07T07:49:34.683+0000] {taskinstance.py:2578} INFO - 0 downstream tasks scheduled from follow-on schedule check
