[2023-03-07T06:09:58.943+0000] {taskinstance.py:1083} INFO - Dependencies all met for <TaskInstance: hook_dag.hook_task scheduled__2018-11-05T10:00:00+00:00 [queued]>
[2023-03-07T06:09:58.954+0000] {taskinstance.py:1083} INFO - Dependencies all met for <TaskInstance: hook_dag.hook_task scheduled__2018-11-05T10:00:00+00:00 [queued]>
[2023-03-07T06:09:58.954+0000] {taskinstance.py:1279} INFO - 
--------------------------------------------------------------------------------
[2023-03-07T06:09:58.954+0000] {taskinstance.py:1280} INFO - Starting attempt 2 of 2
[2023-03-07T06:09:58.955+0000] {taskinstance.py:1281} INFO - 
--------------------------------------------------------------------------------
[2023-03-07T06:09:58.969+0000] {taskinstance.py:1300} INFO - Executing <Task(PythonOperator): hook_task> on 2018-11-05 10:00:00+00:00
[2023-03-07T06:09:58.976+0000] {standard_task_runner.py:55} INFO - Started process 1740 to run task
[2023-03-07T06:09:58.981+0000] {standard_task_runner.py:82} INFO - Running: ['***', 'tasks', 'run', 'hook_dag', 'hook_task', 'scheduled__2018-11-05T10:00:00+00:00', '--job-id', '34', '--raw', '--subdir', 'DAGS_FOLDER/pg-hook.py', '--cfg-path', '/tmp/tmpn8mgfaeh']
[2023-03-07T06:09:58.982+0000] {standard_task_runner.py:83} INFO - Job 34: Subtask hook_task
[2023-03-07T06:09:59.073+0000] {task_command.py:388} INFO - Running <TaskInstance: hook_dag.hook_task scheduled__2018-11-05T10:00:00+00:00 [running]> on host 4d3923509bb6
[2023-03-07T06:09:59.157+0000] {taskinstance.py:1509} INFO - Exporting the following env vars:
AIRFLOW_CTX_DAG_OWNER=***
AIRFLOW_CTX_DAG_ID=hook_dag
AIRFLOW_CTX_TASK_ID=hook_task
AIRFLOW_CTX_EXECUTION_DATE=2018-11-05T10:00:00+00:00
AIRFLOW_CTX_TRY_NUMBER=2
AIRFLOW_CTX_DAG_RUN_ID=scheduled__2018-11-05T10:00:00+00:00
[2023-03-07T06:09:59.167+0000] {base.py:73} INFO - Using connection ID 'postgre_sql' for task execution.
[2023-03-07T06:09:59.169+0000] {taskinstance.py:1768} ERROR - Task failed with exception
Traceback (most recent call last):
  File "/home/airflow/.local/lib/python3.7/site-packages/airflow/operators/python.py", line 175, in execute
    return_value = self.execute_callable()
  File "/home/airflow/.local/lib/python3.7/site-packages/airflow/operators/python.py", line 192, in execute_callable
    return self.python_callable(*self.op_args, **self.op_kwargs)
  File "/opt/airflow/dags/pg-hook.py", line 19, in get_activated_sources
    connection = pg_hook.get_conn()
  File "/home/airflow/.local/lib/python3.7/site-packages/airflow/providers/postgres/hooks/postgres.py", line 144, in get_conn
    self.conn = psycopg2.connect(**conn_args)
  File "/home/airflow/.local/lib/python3.7/site-packages/psycopg2/__init__.py", line 122, in connect
    conn = _connect(dsn, connection_factory=connection_factory, **kwasync)
psycopg2.OperationalError: connection to server at "localhost" (127.0.0.1), port 5432 failed: Connection refused
	Is the server running on that host and accepting TCP/IP connections?
connection to server at "localhost" (::1), port 5432 failed: Cannot assign requested address
	Is the server running on that host and accepting TCP/IP connections?

[2023-03-07T06:09:59.178+0000] {taskinstance.py:1323} INFO - Marking task as FAILED. dag_id=hook_dag, task_id=hook_task, execution_date=20181105T100000, start_date=20230307T060958, end_date=20230307T060959
[2023-03-07T06:09:59.191+0000] {standard_task_runner.py:105} ERROR - Failed to execute job 34 for task hook_task (connection to server at "localhost" (127.0.0.1), port 5432 failed: Connection refused
	Is the server running on that host and accepting TCP/IP connections?
connection to server at "localhost" (::1), port 5432 failed: Cannot assign requested address
	Is the server running on that host and accepting TCP/IP connections?
; 1740)
[2023-03-07T06:09:59.233+0000] {local_task_job.py:208} INFO - Task exited with return code 1
[2023-03-07T06:09:59.252+0000] {taskinstance.py:2578} INFO - 0 downstream tasks scheduled from follow-on schedule check
