[2023-02-28T07:46:56.508+0000] {taskinstance.py:1083} INFO - Dependencies all met for <TaskInstance: api_dag.save_posts manual__2023-02-28T07:46:54.885634+00:00 [queued]>
[2023-02-28T07:46:56.524+0000] {taskinstance.py:1083} INFO - Dependencies all met for <TaskInstance: api_dag.save_posts manual__2023-02-28T07:46:54.885634+00:00 [queued]>
[2023-02-28T07:46:56.525+0000] {taskinstance.py:1279} INFO - 
--------------------------------------------------------------------------------
[2023-02-28T07:46:56.525+0000] {taskinstance.py:1280} INFO - Starting attempt 1 of 1
[2023-02-28T07:46:56.525+0000] {taskinstance.py:1281} INFO - 
--------------------------------------------------------------------------------
[2023-02-28T07:46:56.553+0000] {taskinstance.py:1300} INFO - Executing <Task(PythonOperator): save_posts> on 2023-02-28 07:46:54.885634+00:00
[2023-02-28T07:46:56.559+0000] {standard_task_runner.py:55} INFO - Started process 11434 to run task
[2023-02-28T07:46:56.567+0000] {standard_task_runner.py:82} INFO - Running: ['***', 'tasks', 'run', 'api_dag', 'save_posts', 'manual__2023-02-28T07:46:54.885634+00:00', '--job-id', '4', '--raw', '--subdir', 'DAGS_FOLDER/api_dag.py', '--cfg-path', '/tmp/tmpcdkxllcm']
[2023-02-28T07:46:56.568+0000] {standard_task_runner.py:83} INFO - Job 4: Subtask save_posts
[2023-02-28T07:46:56.712+0000] {task_command.py:388} INFO - Running <TaskInstance: api_dag.save_posts manual__2023-02-28T07:46:54.885634+00:00 [running]> on host 6247a2c7df54
[2023-02-28T07:46:57.000+0000] {taskinstance.py:1509} INFO - Exporting the following env vars:
AIRFLOW_CTX_DAG_OWNER=***
AIRFLOW_CTX_DAG_ID=api_dag
AIRFLOW_CTX_TASK_ID=save_posts
AIRFLOW_CTX_EXECUTION_DATE=2023-02-28T07:46:54.885634+00:00
AIRFLOW_CTX_TRY_NUMBER=1
AIRFLOW_CTX_DAG_RUN_ID=manual__2023-02-28T07:46:54.885634+00:00
[2023-02-28T07:46:57.003+0000] {taskinstance.py:1768} ERROR - Task failed with exception
Traceback (most recent call last):
  File "/home/airflow/.local/lib/python3.7/site-packages/airflow/operators/python.py", line 175, in execute
    return_value = self.execute_callable()
  File "/home/airflow/.local/lib/python3.7/site-packages/airflow/operators/python.py", line 192, in execute_callable
    return self.python_callable(*self.op_args, **self.op_kwargs)
  File "/opt/airflow/dags/api_dag.py", line 10, in save_posts
    with open('/home/rizky/COE/airflow-latihan2/data/posts.json', 'w') as f:
FileNotFoundError: [Errno 2] No such file or directory: '/home/rizky/COE/airflow-latihan2/data/posts.json'
[2023-02-28T07:46:57.021+0000] {taskinstance.py:1323} INFO - Marking task as FAILED. dag_id=api_dag, task_id=save_posts, execution_date=20230228T074654, start_date=20230228T074656, end_date=20230228T074657
[2023-02-28T07:46:57.072+0000] {standard_task_runner.py:105} ERROR - Failed to execute job 4 for task save_posts ([Errno 2] No such file or directory: '/home/rizky/COE/airflow-latihan2/data/posts.json'; 11434)
[2023-02-28T07:46:57.116+0000] {local_task_job.py:208} INFO - Task exited with return code 1
[2023-02-28T07:46:57.144+0000] {taskinstance.py:2578} INFO - 0 downstream tasks scheduled from follow-on schedule check
